2019-06-08 22:26:03,548 -  nornir.core -     INFO -        run() - Running task 'napalm_get' with args {'getters': ['facts']} on 2 hosts
2019-06-08 22:26:24,142 -  nornir.core -     INFO -        run() - Running task 'napalm_get' with args {'getters': ['facts']} on 7 hosts
2019-06-08 22:38:21,221 -  nornir.core -     INFO -        run() - Running task 'collect_ping_results' with args {'remote_ip': ['10.22.33.33', '10.2.6.6', '10.2.3.3']} on 1 hosts
2019-06-08 22:38:21,225 -  nornir.core -     INFO -        run() - Running task 'collect_ping_results' with args {'remote_ip': ['10.5.8.5', '10.8.10.10']} on 1 hosts
2019-06-08 22:38:21,229 -  nornir.core -     INFO -        run() - Running task 'collect_ping_results' with args {'remote_ip': ['10.111.13.13', '10.11.13.13', '10.5.11.5']} on 1 hosts
2019-06-08 22:38:21,234 -  nornir.core -     INFO -        run() - Running task 'collect_ping_results' with args {'remote_ip': ['10.5.11.11', '10.5.8.8', '10.5.10.10']} on 1 hosts
2019-06-08 22:38:21,237 -  nornir.core -     INFO -        run() - Running task 'collect_ping_results' with args {'remote_ip': ['10.111.13.11', '10.11.13.11']} on 1 hosts
2019-06-08 22:38:21,242 -  nornir.core -     INFO -        run() - Running task 'collect_ping_results' with args {'remote_ip': ['10.6.7.7', '10.2.6.2']} on 1 hosts
2019-06-08 22:38:21,245 -  nornir.core -     INFO -        run() - Running task 'collect_ping_results' with args {'remote_ip': ['10.22.33.22', '10.2.3.2']} on 1 hosts
2019-06-08 22:38:21,250 -  nornir.core -     INFO -        run() - Running task 'collect_ping_results' with args {'remote_ip': ['10.7.10.10', '10.6.7.6']} on 1 hosts
2019-06-08 22:38:21,253 -  nornir.core -     INFO -        run() - Running task 'collect_ping_results' with args {'remote_ip': ['10.8.10.8', '10.7.10.7', '10.5.10.5']} on 1 hosts
2019-06-08 22:39:02,342 -  nornir.core -     INFO -        run() - Running task 'check_bgp_table' with args {} on 1 hosts
2019-06-08 22:39:53,033 -  nornir.core -     INFO -        run() - Running task 'xr_multiple' with args {} on 2 hosts
2019-06-08 22:40:00,193 -  nornir.core -     INFO -        run() - Running task 'napalm_get' with args {'getters': ['optics', 'interfaces']} on 7 hosts
2019-06-08 22:40:44,376 -  nornir.core -     INFO -        run() - Running task 'netmiko_send_command' with args {'command_string': 'admin show platform', 'use_textfsm': True} on 2 hosts
2019-06-08 22:40:51,733 -  nornir.core -     INFO -        run() - Running task 'get_cards_jnp' with args {} on 7 hosts
2019-06-08 22:40:52,695 - nornir.core.task -    ERROR -      start() - Host 'ke-p6-nbi': task 'get_cards_jnp' failed with traceback:
Traceback (most recent call last):
  File "/usr/local/lib/python3.7/site-packages/jnpr/junos/device.py", line 774, in execute
    ignore_warning=ignore_warning)
  File "/usr/local/lib/python3.7/site-packages/jnpr/junos/decorators.py", line 169, in wrapper
    raise ex
  File "/usr/local/lib/python3.7/site-packages/jnpr/junos/decorators.py", line 116, in wrapper
    rsp = function(self, *args, **kwargs)
  File "/usr/local/lib/python3.7/site-packages/jnpr/junos/device.py", line 1336, in _rpc_reply
    return self._conn.rpc(rpc_cmd_e)._NCElement__doc
  File "/usr/local/lib/python3.7/site-packages/ncclient/manager.py", line 216, in execute
    raise_mode=self._raise_mode).request(*args, **kwds)
  File "/usr/local/lib/python3.7/site-packages/ncclient/operations/third_party/juniper/rpc.py", line 46, in request
    return self._request(rpc)
  File "/usr/local/lib/python3.7/site-packages/ncclient/operations/rpc.py", line 341, in _request
    raise self._reply.error
ncclient.operations.rpc.RPCError: 
the chassis-control subsystem is not responding to management requests


During handling of the above exception, another exception occurred:

Traceback (most recent call last):
  File "/opt/lnetd/inputs/nornir/mutils.py", line 72, in get_cards_jnp
    module = ModuleTable(dev).get()
  File "/usr/local/lib/python3.7/site-packages/jnpr/junos/factory/optable.py", line 64, in get
    self.xml = getattr(self.RPC, self.GET_RPC)(**rpc_args)
  File "/usr/local/lib/python3.7/site-packages/jnpr/junos/rpcmeta.py", line 345, in _exec_rpc
    return self._junos.execute(rpc, **dec_args)
  File "/usr/local/lib/python3.7/site-packages/jnpr/junos/decorators.py", line 63, in wrapper
    result = function(*args, **kwargs)
  File "/usr/local/lib/python3.7/site-packages/jnpr/junos/decorators.py", line 31, in wrapper
    return function(*args, **kwargs)
  File "/usr/local/lib/python3.7/site-packages/jnpr/junos/device.py", line 794, in execute
    errs=ex)
jnpr.junos.exception.RpcError: RpcError(severity: error, bad_element: None, message: the chassis-control subsystem is not responding to management requests)

During handling of the above exception, another exception occurred:

Traceback (most recent call last):
  File "/usr/local/lib/python3.7/site-packages/nornir/core/task.py", line 67, in start
    r = self.task(self, **self.params)
  File "/opt/lnetd/inputs/nornir/mutils.py", line 87, in get_cards_jnp
    raise Exception
Exception

2019-06-08 22:40:52,768 - nornir.core.task -    ERROR -      start() - Host 'ke-pe2-nbi': task 'get_cards_jnp' failed with traceback:
Traceback (most recent call last):
  File "/usr/local/lib/python3.7/site-packages/jnpr/junos/device.py", line 774, in execute
    ignore_warning=ignore_warning)
  File "/usr/local/lib/python3.7/site-packages/jnpr/junos/decorators.py", line 169, in wrapper
    raise ex
  File "/usr/local/lib/python3.7/site-packages/jnpr/junos/decorators.py", line 116, in wrapper
    rsp = function(self, *args, **kwargs)
  File "/usr/local/lib/python3.7/site-packages/jnpr/junos/device.py", line 1336, in _rpc_reply
    return self._conn.rpc(rpc_cmd_e)._NCElement__doc
  File "/usr/local/lib/python3.7/site-packages/ncclient/manager.py", line 216, in execute
    raise_mode=self._raise_mode).request(*args, **kwds)
  File "/usr/local/lib/python3.7/site-packages/ncclient/operations/third_party/juniper/rpc.py", line 46, in request
    return self._request(rpc)
  File "/usr/local/lib/python3.7/site-packages/ncclient/operations/rpc.py", line 341, in _request
    raise self._reply.error
ncclient.operations.rpc.RPCError: 
the chassis-control subsystem is not responding to management requests


During handling of the above exception, another exception occurred:

Traceback (most recent call last):
  File "/opt/lnetd/inputs/nornir/mutils.py", line 72, in get_cards_jnp
    module = ModuleTable(dev).get()
  File "/usr/local/lib/python3.7/site-packages/jnpr/junos/factory/optable.py", line 64, in get
    self.xml = getattr(self.RPC, self.GET_RPC)(**rpc_args)
  File "/usr/local/lib/python3.7/site-packages/jnpr/junos/rpcmeta.py", line 345, in _exec_rpc
    return self._junos.execute(rpc, **dec_args)
  File "/usr/local/lib/python3.7/site-packages/jnpr/junos/decorators.py", line 63, in wrapper
    result = function(*args, **kwargs)
  File "/usr/local/lib/python3.7/site-packages/jnpr/junos/decorators.py", line 31, in wrapper
    return function(*args, **kwargs)
  File "/usr/local/lib/python3.7/site-packages/jnpr/junos/device.py", line 794, in execute
    errs=ex)
jnpr.junos.exception.RpcError: RpcError(severity: error, bad_element: None, message: the chassis-control subsystem is not responding to management requests)

During handling of the above exception, another exception occurred:

Traceback (most recent call last):
  File "/usr/local/lib/python3.7/site-packages/nornir/core/task.py", line 67, in start
    r = self.task(self, **self.params)
  File "/opt/lnetd/inputs/nornir/mutils.py", line 87, in get_cards_jnp
    raise Exception
Exception

2019-06-08 22:40:53,088 - nornir.core.task -    ERROR -      start() - Host 'gb-p10-lon': task 'get_cards_jnp' failed with traceback:
Traceback (most recent call last):
  File "/usr/local/lib/python3.7/site-packages/jnpr/junos/device.py", line 774, in execute
    ignore_warning=ignore_warning)
  File "/usr/local/lib/python3.7/site-packages/jnpr/junos/decorators.py", line 169, in wrapper
    raise ex
  File "/usr/local/lib/python3.7/site-packages/jnpr/junos/decorators.py", line 116, in wrapper
    rsp = function(self, *args, **kwargs)
  File "/usr/local/lib/python3.7/site-packages/jnpr/junos/device.py", line 1336, in _rpc_reply
    return self._conn.rpc(rpc_cmd_e)._NCElement__doc
  File "/usr/local/lib/python3.7/site-packages/ncclient/manager.py", line 216, in execute
    raise_mode=self._raise_mode).request(*args, **kwds)
  File "/usr/local/lib/python3.7/site-packages/ncclient/operations/third_party/juniper/rpc.py", line 46, in request
    return self._request(rpc)
  File "/usr/local/lib/python3.7/site-packages/ncclient/operations/rpc.py", line 341, in _request
    raise self._reply.error
ncclient.operations.rpc.RPCError: 
the chassis-control subsystem is not responding to management requests


During handling of the above exception, another exception occurred:

Traceback (most recent call last):
  File "/opt/lnetd/inputs/nornir/mutils.py", line 72, in get_cards_jnp
    module = ModuleTable(dev).get()
  File "/usr/local/lib/python3.7/site-packages/jnpr/junos/factory/optable.py", line 64, in get
    self.xml = getattr(self.RPC, self.GET_RPC)(**rpc_args)
  File "/usr/local/lib/python3.7/site-packages/jnpr/junos/rpcmeta.py", line 345, in _exec_rpc
    return self._junos.execute(rpc, **dec_args)
  File "/usr/local/lib/python3.7/site-packages/jnpr/junos/decorators.py", line 63, in wrapper
    result = function(*args, **kwargs)
  File "/usr/local/lib/python3.7/site-packages/jnpr/junos/decorators.py", line 31, in wrapper
    return function(*args, **kwargs)
  File "/usr/local/lib/python3.7/site-packages/jnpr/junos/device.py", line 794, in execute
    errs=ex)
jnpr.junos.exception.RpcError: RpcError(severity: error, bad_element: None, message: the chassis-control subsystem is not responding to management requests)

During handling of the above exception, another exception occurred:

Traceback (most recent call last):
  File "/usr/local/lib/python3.7/site-packages/nornir/core/task.py", line 67, in start
    r = self.task(self, **self.params)
  File "/opt/lnetd/inputs/nornir/mutils.py", line 87, in get_cards_jnp
    raise Exception
Exception

2019-06-08 22:40:53,206 - nornir.core.task -    ERROR -      start() - Host 'gb-pe5-lon': task 'get_cards_jnp' failed with traceback:
Traceback (most recent call last):
  File "/usr/local/lib/python3.7/site-packages/jnpr/junos/device.py", line 774, in execute
    ignore_warning=ignore_warning)
  File "/usr/local/lib/python3.7/site-packages/jnpr/junos/decorators.py", line 169, in wrapper
    raise ex
  File "/usr/local/lib/python3.7/site-packages/jnpr/junos/decorators.py", line 116, in wrapper
    rsp = function(self, *args, **kwargs)
  File "/usr/local/lib/python3.7/site-packages/jnpr/junos/device.py", line 1336, in _rpc_reply
    return self._conn.rpc(rpc_cmd_e)._NCElement__doc
  File "/usr/local/lib/python3.7/site-packages/ncclient/manager.py", line 216, in execute
    raise_mode=self._raise_mode).request(*args, **kwds)
  File "/usr/local/lib/python3.7/site-packages/ncclient/operations/third_party/juniper/rpc.py", line 46, in request
    return self._request(rpc)
  File "/usr/local/lib/python3.7/site-packages/ncclient/operations/rpc.py", line 341, in _request
    raise self._reply.error
ncclient.operations.rpc.RPCError: 
the chassis-control subsystem is not responding to management requests


During handling of the above exception, another exception occurred:

Traceback (most recent call last):
  File "/opt/lnetd/inputs/nornir/mutils.py", line 72, in get_cards_jnp
    module = ModuleTable(dev).get()
  File "/usr/local/lib/python3.7/site-packages/jnpr/junos/factory/optable.py", line 64, in get
    self.xml = getattr(self.RPC, self.GET_RPC)(**rpc_args)
  File "/usr/local/lib/python3.7/site-packages/jnpr/junos/rpcmeta.py", line 345, in _exec_rpc
    return self._junos.execute(rpc, **dec_args)
  File "/usr/local/lib/python3.7/site-packages/jnpr/junos/decorators.py", line 63, in wrapper
    result = function(*args, **kwargs)
  File "/usr/local/lib/python3.7/site-packages/jnpr/junos/decorators.py", line 31, in wrapper
    return function(*args, **kwargs)
  File "/usr/local/lib/python3.7/site-packages/jnpr/junos/device.py", line 794, in execute
    errs=ex)
jnpr.junos.exception.RpcError: RpcError(severity: error, bad_element: None, message: the chassis-control subsystem is not responding to management requests)

During handling of the above exception, another exception occurred:

Traceback (most recent call last):
  File "/usr/local/lib/python3.7/site-packages/nornir/core/task.py", line 67, in start
    r = self.task(self, **self.params)
  File "/opt/lnetd/inputs/nornir/mutils.py", line 87, in get_cards_jnp
    raise Exception
Exception

2019-06-08 22:40:53,393 - nornir.core.task -    ERROR -      start() - Host 'gb-pe8-lon': task 'get_cards_jnp' failed with traceback:
Traceback (most recent call last):
  File "/opt/lnetd/inputs/nornir/mutils.py", line 77, in get_cards_jnp
    if re.search(r"FPC|Routing|PIC",module):
  File "/usr/local/lib/python3.7/re.py", line 183, in search
    return _compile(pattern, flags).search(string)
TypeError: expected string or bytes-like object

During handling of the above exception, another exception occurred:

Traceback (most recent call last):
  File "/usr/local/lib/python3.7/site-packages/nornir/core/task.py", line 67, in start
    r = self.task(self, **self.params)
  File "/opt/lnetd/inputs/nornir/mutils.py", line 87, in get_cards_jnp
    raise Exception
Exception

2019-06-08 22:41:02,274 - nornir.core.task -    ERROR -      start() - Host 'ke-pe3-nbi': task 'get_cards_jnp' failed with traceback:
Traceback (most recent call last):
  File "/usr/local/lib/python3.7/site-packages/jnpr/junos/device.py", line 774, in execute
    ignore_warning=ignore_warning)
  File "/usr/local/lib/python3.7/site-packages/jnpr/junos/decorators.py", line 116, in wrapper
    rsp = function(self, *args, **kwargs)
  File "/usr/local/lib/python3.7/site-packages/jnpr/junos/device.py", line 1336, in _rpc_reply
    return self._conn.rpc(rpc_cmd_e)._NCElement__doc
  File "/usr/local/lib/python3.7/site-packages/ncclient/manager.py", line 216, in execute
    raise_mode=self._raise_mode).request(*args, **kwds)
  File "/usr/local/lib/python3.7/site-packages/ncclient/operations/third_party/juniper/rpc.py", line 46, in request
    return self._request(rpc)
  File "/usr/local/lib/python3.7/site-packages/ncclient/operations/rpc.py", line 347, in _request
    raise TimeoutExpiredError('ncclient timed out while waiting for an rpc reply.')
ncclient.operations.errors.TimeoutExpiredError: ncclient timed out while waiting for an rpc reply.

During handling of the above exception, another exception occurred:

Traceback (most recent call last):
  File "/opt/lnetd/inputs/nornir/mutils.py", line 72, in get_cards_jnp
    module = ModuleTable(dev).get()
  File "/usr/local/lib/python3.7/site-packages/jnpr/junos/factory/optable.py", line 64, in get
    self.xml = getattr(self.RPC, self.GET_RPC)(**rpc_args)
  File "/usr/local/lib/python3.7/site-packages/jnpr/junos/rpcmeta.py", line 345, in _exec_rpc
    return self._junos.execute(rpc, **dec_args)
  File "/usr/local/lib/python3.7/site-packages/jnpr/junos/decorators.py", line 63, in wrapper
    result = function(*args, **kwargs)
  File "/usr/local/lib/python3.7/site-packages/jnpr/junos/decorators.py", line 31, in wrapper
    return function(*args, **kwargs)
  File "/usr/local/lib/python3.7/site-packages/jnpr/junos/device.py", line 778, in execute
    raise EzErrors.RpcTimeoutError(self, rpc_cmd_e.tag, self.timeout)
jnpr.junos.exception.RpcTimeoutError: RpcTimeoutError(host: ke-pe3-nbi, cmd: get-chassis-inventory, timeout: 10)

During handling of the above exception, another exception occurred:

Traceback (most recent call last):
  File "/usr/local/lib/python3.7/site-packages/nornir/core/task.py", line 67, in start
    r = self.task(self, **self.params)
  File "/opt/lnetd/inputs/nornir/mutils.py", line 87, in get_cards_jnp
    raise Exception
Exception

2019-06-08 22:41:02,906 - nornir.core.task -    ERROR -      start() - Host 'fr-p7-mrs': task 'get_cards_jnp' failed with traceback:
Traceback (most recent call last):
  File "/usr/local/lib/python3.7/site-packages/jnpr/junos/device.py", line 774, in execute
    ignore_warning=ignore_warning)
  File "/usr/local/lib/python3.7/site-packages/jnpr/junos/decorators.py", line 116, in wrapper
    rsp = function(self, *args, **kwargs)
  File "/usr/local/lib/python3.7/site-packages/jnpr/junos/device.py", line 1336, in _rpc_reply
    return self._conn.rpc(rpc_cmd_e)._NCElement__doc
  File "/usr/local/lib/python3.7/site-packages/ncclient/manager.py", line 216, in execute
    raise_mode=self._raise_mode).request(*args, **kwds)
  File "/usr/local/lib/python3.7/site-packages/ncclient/operations/third_party/juniper/rpc.py", line 46, in request
    return self._request(rpc)
  File "/usr/local/lib/python3.7/site-packages/ncclient/operations/rpc.py", line 347, in _request
    raise TimeoutExpiredError('ncclient timed out while waiting for an rpc reply.')
ncclient.operations.errors.TimeoutExpiredError: ncclient timed out while waiting for an rpc reply.

During handling of the above exception, another exception occurred:

Traceback (most recent call last):
  File "/opt/lnetd/inputs/nornir/mutils.py", line 72, in get_cards_jnp
    module = ModuleTable(dev).get()
  File "/usr/local/lib/python3.7/site-packages/jnpr/junos/factory/optable.py", line 64, in get
    self.xml = getattr(self.RPC, self.GET_RPC)(**rpc_args)
  File "/usr/local/lib/python3.7/site-packages/jnpr/junos/rpcmeta.py", line 345, in _exec_rpc
    return self._junos.execute(rpc, **dec_args)
  File "/usr/local/lib/python3.7/site-packages/jnpr/junos/decorators.py", line 63, in wrapper
    result = function(*args, **kwargs)
  File "/usr/local/lib/python3.7/site-packages/jnpr/junos/decorators.py", line 31, in wrapper
    return function(*args, **kwargs)
  File "/usr/local/lib/python3.7/site-packages/jnpr/junos/device.py", line 778, in execute
    raise EzErrors.RpcTimeoutError(self, rpc_cmd_e.tag, self.timeout)
jnpr.junos.exception.RpcTimeoutError: RpcTimeoutError(host: fr-p7-mrs, cmd: get-chassis-inventory, timeout: 10)

During handling of the above exception, another exception occurred:

Traceback (most recent call last):
  File "/usr/local/lib/python3.7/site-packages/nornir/core/task.py", line 67, in start
    r = self.task(self, **self.params)
  File "/opt/lnetd/inputs/nornir/mutils.py", line 87, in get_cards_jnp
    raise Exception
Exception

