2020-08-26 16:27:42,666 -  nornir.core -     INFO -        run() - Running task 'get_bgp_peers' with args {'progress_bar': Get BGP Peers:   0%|                                                                                                                                                                | 0/5 [00:00<?, ?it/s]} on 5 hosts
2020-08-26 16:27:42,784 - nornir.core.task -    ERROR -      start() - Host 'gb-pe5-lon': task 'Get BGP peer from device' failed with traceback:
Traceback (most recent call last):
  File "/usr/local/lib/python3.7/site-packages/nornir/core/task.py", line 85, in start
    r = self.task(self, **self.params)
  File "/usr/local/lib/python3.7/site-packages/nornir/plugins/tasks/networking/napalm_get.py", line 49, in napalm_get
    device = task.host.get_connection("napalm", task.nornir.config)
  File "/usr/local/lib/python3.7/site-packages/nornir/core/inventory.py", line 302, in get_connection
    extras=conn.extras,
  File "/usr/local/lib/python3.7/site-packages/nornir/core/inventory.py", line 352, in open_connection
    configuration=configuration,
  File "/usr/local/lib/python3.7/site-packages/nornir/plugins/connections/napalm.py", line 49, in open
    network_driver = get_network_driver(platform)
  File "/usr/local/lib/python3.7/site-packages/napalm/base/__init__.py", line 74, in get_network_driver
    raise ModuleImportError("Please provide a valid driver name.")
napalm.base.exceptions.ModuleImportError: Please provide a valid driver name.

2020-08-26 16:27:42,785 - nornir.core.task -    ERROR -      start() - Host 'gb-pe5-lon': task 'get_bgp_peers' failed with traceback:
Traceback (most recent call last):
  File "/usr/local/lib/python3.7/site-packages/nornir/core/task.py", line 85, in start
    r = self.task(self, **self.params)
  File "get_bgp_peers.py", line 57, in get_bgp_peers
    severity_level=logging.INFO)
  File "/usr/local/lib/python3.7/site-packages/nornir/core/task.py", line 147, in run
    raise NornirSubTaskError(task=task, result=r)
nornir.core.exceptions.NornirSubTaskError: Subtask: <function napalm_get at 0x7f17ce2c4840> (failed)


2020-08-26 16:45:41,173 -  nornir.core -     INFO -        run() - Running task 'get_bgp_peers' with args {'progress_bar': Get BGP Peers:   0%|                                                                                                                                                                | 0/5 [00:00<?, ?it/s]} on 5 hosts
2020-08-26 16:47:15,342 -  nornir.core -     INFO -        run() - Running task 'get_bgp_peers' with args {'progress_bar': Get BGP Peers:   0%|                                                                                                                                                                | 0/5 [00:00<?, ?it/s]} on 5 hosts
2020-08-26 16:52:06,836 -  nornir.core -  WARNING -        run() - Task 'netmiko_send_command' has not been run – 0 hosts selected
2020-08-26 16:52:06,957 -  nornir.core -     INFO -        run() - Running task 'get_cards_jnp' with args {} on 7 hosts
2020-08-26 16:52:13,818 -  nornir.core -  WARNING -        run() - Task 'huawei_multiple' has not been run – 0 hosts selected
2020-08-26 17:07:58,531 -  nornir.core -  WARNING -        run() - Task 'netmiko_send_command' has not been run – 0 hosts selected
2020-08-26 17:07:58,534 -  nornir.core -  WARNING -        run() - Task 'napalm_get' has not been run – 0 hosts selected
2020-08-26 17:07:58,535 -  nornir.core -     INFO -        run() - Running task 'napalm_get' with args {'getters': ['facts']} on 1 hosts
2020-08-26 17:08:31,733 - nornir.core.task -    ERROR -      start() - Host 'gb-pe11-lon': task 'napalm_get' failed with traceback:
Traceback (most recent call last):
  File "/home/lab/lnetd_11_march/lib/python3.7/site-packages/paramiko/channel.py", line 699, in recv
    out = self.in_buffer.read(nbytes, self.timeout)
  File "/home/lab/lnetd_11_march/lib/python3.7/site-packages/paramiko/buffered_pipe.py", line 164, in read
    raise PipeTimeout()
paramiko.buffered_pipe.PipeTimeout

During handling of the above exception, another exception occurred:

Traceback (most recent call last):
  File "/home/lab/lnetd_11_march/lib/python3.7/site-packages/netmiko/base_connection.py", line 541, in _read_channel_expect
    new_data = self.remote_conn.recv(MAX_BUFFER)
  File "/home/lab/lnetd_11_march/lib/python3.7/site-packages/paramiko/channel.py", line 701, in recv
    raise socket.timeout()
socket.timeout

During handling of the above exception, another exception occurred:

Traceback (most recent call last):
  File "/home/lab/lnetd_11_march/lib/python3.7/site-packages/nornir/core/task.py", line 85, in start
    r = self.task(self, **self.params)
  File "/home/lab/lnetd_11_march/lib/python3.7/site-packages/nornir/plugins/tasks/networking/napalm_get.py", line 61, in napalm_get
    result[g] = method(**options)
  File "/home/lab/lnetd_11_march/lib/python3.7/site-packages/napalm/iosxr/iosxr.py", line 163, in get_facts
    facts_rpc_reply = ETREE.fromstring(self.device.make_rpc_call(facts_rpc_request))
  File "/home/lab/lnetd_11_march/lib/python3.7/site-packages/pyIOSXR/iosxr.py", line 151, in make_rpc_call
    result = self._execute_rpc(rpc_command)
  File "/home/lab/lnetd_11_march/lib/python3.7/site-packages/pyIOSXR/iosxr.py", line 365, in _execute_rpc
    response = self._send_command(xml_rpc_command, delay_factor=delay_factor)
  File "/home/lab/lnetd_11_march/lib/python3.7/site-packages/pyIOSXR/iosxr.py", line 275, in _send_command
    max_loops=max_loops)
  File "/home/lab/lnetd_11_march/lib/python3.7/site-packages/netmiko/base_connection.py", line 1447, in send_command_expect
    return self.send_command(*args, **kwargs)
  File "/home/lab/lnetd_11_march/lib/python3.7/site-packages/netmiko/base_connection.py", line 1366, in send_command
    new_data = self.read_until_pattern(pattern=re.escape(cmd))
  File "/home/lab/lnetd_11_march/lib/python3.7/site-packages/netmiko/base_connection.py", line 618, in read_until_pattern
    return self._read_channel_expect(*args, **kwargs)
  File "/home/lab/lnetd_11_march/lib/python3.7/site-packages/netmiko/base_connection.py", line 552, in _read_channel_expect
    "Timed-out reading channel, data not available."
netmiko.ssh_exception.NetmikoTimeoutException: Timed-out reading channel, data not available.

2020-08-26 17:08:31,744 -  nornir.core -     INFO -        run() - Running task 'collect_xr_multiple' with args {'progress_bar': Get Model Number for XR using Genie parser:   0%|                                                                                                                                   | 0/1 [00:00<?, ?it/s]} on 1 hosts
2020-08-26 17:08:41,716 -  nornir.core -     INFO -        run() - Running task '_napalm_get' with args {'progress_bar': Get Model Number for Juniper using Napalm:   0%|                                                                                                                                    | 0/7 [00:00<?, ?it/s]} on 7 hosts
2020-08-26 17:11:02,041 -  nornir.core -  WARNING -        run() - Task 'netmiko_send_command' has not been run – 0 hosts selected
2020-08-26 17:11:02,043 -  nornir.core -  WARNING -        run() - Task 'napalm_get' has not been run – 0 hosts selected
2020-08-26 17:11:02,044 -  nornir.core -     INFO -        run() - Running task 'napalm_get' with args {'getters': ['facts']} on 1 hosts
2020-08-26 17:11:07,062 - nornir.core.task -    ERROR -      start() - Host 'gb-pe11-lon': task 'napalm_get' failed with traceback:
Traceback (most recent call last):
  File "/home/lab/lnetd_11_march/lib/python3.7/site-packages/nornir/core/task.py", line 85, in start
    r = self.task(self, **self.params)
  File "/home/lab/lnetd_11_march/lib/python3.7/site-packages/nornir/plugins/tasks/networking/napalm_get.py", line 49, in napalm_get
    device = task.host.get_connection("napalm", task.nornir.config)
  File "/home/lab/lnetd_11_march/lib/python3.7/site-packages/nornir/core/inventory.py", line 305, in get_connection
    extras=conn.extras,
  File "/home/lab/lnetd_11_march/lib/python3.7/site-packages/nornir/core/inventory.py", line 365, in open_connection
    configuration=configuration,
  File "/home/lab/lnetd_11_march/lib/python3.7/site-packages/nornir/plugins/connections/napalm.py", line 51, in open
    connection.open()
  File "/home/lab/lnetd_11_march/lib/python3.7/site-packages/napalm/iosxr/iosxr.py", line 80, in open
    self.device.open()
  File "/home/lab/lnetd_11_march/lib/python3.7/site-packages/pyIOSXR/iosxr.py", line 166, in open
    **self.netmiko_kwargs)
  File "/home/lab/lnetd_11_march/lib/python3.7/site-packages/netmiko/ssh_dispatcher.py", line 252, in ConnectHandler
    return ConnectionClass(*args, **kwargs)
  File "/home/lab/lnetd_11_march/lib/python3.7/site-packages/netmiko/base_connection.py", line 318, in __init__
    self._open()
  File "/home/lab/lnetd_11_march/lib/python3.7/site-packages/netmiko/base_connection.py", line 324, in _open
    self._try_session_preparation()
  File "/home/lab/lnetd_11_march/lib/python3.7/site-packages/netmiko/base_connection.py", line 747, in _try_session_preparation
    self.session_preparation()
  File "/home/lab/lnetd_11_march/lib/python3.7/site-packages/netmiko/cisco/cisco_xr.py", line 12, in session_preparation
    self.set_terminal_width(command="terminal width 511")
  File "/home/lab/lnetd_11_march/lib/python3.7/site-packages/netmiko/base_connection.py", line 1045, in set_terminal_width
    output = self.read_until_pattern(pattern=re.escape(command.strip()))
  File "/home/lab/lnetd_11_march/lib/python3.7/site-packages/netmiko/base_connection.py", line 618, in read_until_pattern
    return self._read_channel_expect(*args, **kwargs)
  File "/home/lab/lnetd_11_march/lib/python3.7/site-packages/netmiko/base_connection.py", line 543, in _read_channel_expect
    raise EOFError("Channel stream closed by remote device.")
EOFError: Channel stream closed by remote device.

2020-08-26 17:11:38,764 -  nornir.core -     INFO -        run() - Running task 'netmiko_send_command' with args {'command_string': 'admin show platform', 'use_textfsm': True} on 1 hosts
2020-08-26 17:11:48,110 -  nornir.core -     INFO -        run() - Running task 'get_cards_jnp' with args {} on 7 hosts
2020-08-26 17:11:54,835 -  nornir.core -  WARNING -        run() - Task 'huawei_multiple' has not been run – 0 hosts selected
2020-08-26 17:12:37,555 -  nornir.core -     INFO -        run() - Running task 'xr_multiple' with args {} on 1 hosts
2020-08-26 17:12:46,789 -  nornir.core -     INFO -        run() - Running task 'napalm_get' with args {'getters': ['optics', 'interfaces']} on 7 hosts
